Workbook

Sheet Pelitulokset
AH1: Pelaaja nro. --> | AI1: 1 | AJ1: 2 | AK1: 3 | AL1: 4 | AM1: 5 | AN1: 6 | AO1: 7 | AP1: 8 | AQ1: 9 | AR1: 10 | AS1: 11 | AT1: 12 | AU1: 13 | AV1: 14 | AW1: 15 | AX1: 16 | AY1: 17 | AZ1: 18 | BA1: 19 | BB1: 20 | BC1: 21 | BD1: 22 | BE1: 23 | BF1: 24 | BG1: 25 | BH1: 26 | BI1: 27 | BJ1: 28 | BK1: 29 | BL1: 30 | BM1: 31 | BN1: 32 | BO1: 33 | BP1: 34 | BQ1: 35 | BR1: 36 | BS1: 37 | BT1: 38 | BU1: 39 | BV1: 40 | BW1: 41 | BX1: 42 | BY1: 43 | BZ1: 44 | CA1: 45 | CB1: 46 | CC1: 47 | CD1: 48 | CE1: 49 | CF1: 50 | CG1: 51 | CH1: 52 | CI1: 53 | CJ1: 54 | CK1: 55 | CL1: 56 | CM1: 57 | CN1: 58 | CO1: 59 | CP1: 60 | CQ1: 61 | CR1: 62 | CS1: 63 | CT1: 64 | CU1: 65 | CV1: 66 | CW1: 67 | CX1: 68 | CY1: 69 | CZ1: 70 | DA1: 71 | DB1: 72 | DC1: 73 | DD1: 74 | DE1: 75 | DF1: 76 | DG1: 77 | DH1: 78 | DI1: 79 | DJ1: 80 | DK1: 81 | DL1: 82 | DM1: 83 | DN1: 84 | DO1: 85 | DP1: 86 | DQ1: 87 | DR1: 88 | DS1: 89 | DT1: 90 | DU1: 91 | DV1: 92 | DW1: 93 | DX1: 94 | DY1: 95 | DZ1: 96 | EA1: 97 | EB1: 98 | EC1: 99 | ED1: 100 | EE1: Koko kerho ka.
B2: Pelitulosten kirjaukset | H2: Apulaskenta | N2: Laskenta | AI2: Pelaajien juokseva rating
B3: Pelaaja 1 | C3: Pelaaja 2 (heikompi) | D3: Tasoituskivet (heikommalle) | E3: Voittaja (nimi) | F3: päivämäärä | H3: Täyttäminen aloitettu? | I3: Pelaaja 1 olemassa? | J3: Pelaaja 2 olemassa? | K3: Pelaajat eri pelaajia? | L3: Voittaja ilmoitettu oikein? | M3: Kaikki täytetty? | N3: Tiedot syötetty oikein? | O3: Pelaaja 1 rating | P3: Pelaaja 2 rating | Q3: Rating ero (tasoitus huomioiden) | R3: Pelaaja 2 tasoitettu rating | S3: Pelaaja 1 Sa (Tulos) | T3: Pelaaja 1 Beta | U3: Pelaaja 2 Beta | V3: Pelaaja 1 Se (voittotodennäköisyys) | W3: Pelaaja 1 con | X3: Pelaaja 1 bonus | Y3: Pelaaja 1 rating muutos | Z3: Pelaaja 2 Sa (Tulos) | AA3: Pelaaja 2 Se (voittotodennäköisyys) | AB3: Pelaaja 2 con | AC3: Pelaaja 2 bonus | AD3: Pelaaja 2 rating muutos | AE3: Pelaaja 1 pistemuutos (vanha, yksinkertainen) | AF3: Pelaaja 2 pistemuutos (vanha, yksinkertainen) | AI3: {=index('Osallistujat ja seuranta'!$C:$C,AI1+row('Osallistujat ja seuranta'!$B$4),0)} -> Jussa | AJ3: {=index('Osallistujat ja seuranta'!$C:$C,AJ1+row('Osallistujat ja seuranta'!$B$4),0)} -> Peitsa | AK3: {=index('Osallistujat ja seuranta'!$C:$C,AK1+row('Osallistujat ja seuranta'!$B$4),0)} -> Olli | AL3: {=index('Osallistujat ja seuranta'!$C:$C,AL1+row('Osallistujat ja seuranta'!$B$4),0)} -> Lauri | AM3: {=index('Osallistujat ja seuranta'!$C:$C,AM1+row('Osallistujat ja seuranta'!$B$4),0)} -> Tim | AN3: {=index('Osallistujat ja seuranta'!$C:$C,AN1+row('Osallistujat ja seuranta'!$B$4),0)} -> Timo | AO3: {=index('Osallistujat ja seuranta'!$C:$C,AO1+row('Osallistujat ja seuranta'!$B$4),0)} -> Heikki | AP3: {=index('Osallistujat ja seuranta'!$C:$C,AP1+row('Osallistujat ja seuranta'!$B$4),0)} -> Aleksi | ... ED3: {=index('Osallistujat ja seuranta'!$C:$C,ED1+row('Osallistujat ja seuranta'!$B$4),0)}
AH4: Aloitus! | AI4: {=index('Osallistujat ja seuranta'!$E:$E,match(AI3,'Osallistujat ja seuranta'!$C:$C,0),0)} -> 1947.9562 | AJ4: {=index('Osallistujat ja seuranta'!$E:$E,match(AJ3,'Osallistujat ja seuranta'!$C:$C,0),0)} -> 1738.483 | AK4: {=index('Osallistujat ja seuranta'!$E:$E,match(AK3,'Osallistujat ja seuranta'!$C:$C,0),0)} -> 2442.0979 | AL4: {=index('Osallistujat ja seuranta'!$E:$E,match(AL3,'Osallistujat ja seuranta'!$C:$C,0),0)} -> 1676.0117 | AM4: {=index('Osallistujat ja seuranta'!$E:$E,match(AM3,'Osallistujat ja seuranta'!$C:$C,0),0)} -> 1804.0721 | AN4: {=index('Osallistujat ja seuranta'!$E:$E,match(AN3,'Osallistujat ja seuranta'!$C:$C,0),0)} -> 2324.4055 | AO4: {=index('Osallistujat ja seuranta'!$E:$E,match(AO3,'Osallistujat ja seuranta'!$C:$C,0),0)} -> 2286.3278 | AP4: {=index('Osallistujat ja seuranta'!$E:$E,match(AP3,'Osallistujat ja seuranta'!$C:$C,0),0)} -> 1646.0151 | ... ED4: {=index('Osallistujat ja seuranta'!$E:$E,match(ED3,'Osallistujat ja seuranta'!$C:$C,0),0)} -> #N/A | EE4: =sum(iferror(AI4:BH4,0))/count(AI4:BH4) -> 1647.7966
B5: Olli | C5: Peitsa | D5: 5 | E5: Olli | F5: 46106 | H5: =if(countblank(B5:E5)<4,TRUE,FALSE) -> TRUE | I5: =if(iferror(match(B5,'Osallistujat ja seuranta'!C:C,0),0)>0,TRUE,FALSE) -> TRUE | J5: =if(iferror(match(C5,'Osallistujat ja seuranta'!C:C,0),0)>0,TRUE,FALSE) -> TRUE | K5: =not(B5=C5) -> TRUE | L5: =or(E5=B5,E5=C5) -> TRUE | M5: =countblank(B5:E5)=0 -> TRUE | N5: =if(and(I5:M5),1,if(H5,0,"")) -> 1 | O5: =if(N5=1,index(4:4,1,match(B5,$3:$3,0)),"") -> 2442.0979 | P5: =if(N5=1,index(4:4,1,match(C5,$3:$3,0)),"") -> 1738.483 | Q5: =if(N5=1,O5-(P5+D5*100-if(D5>0,50,0))*N5,"") -> 253.61496 | R5: =if(N5=1,P5+D5*100-if(D5>0,50,0),"") -> 2188.483 | S5: =if(E5=B5,1,0) -> 1 | T5: =-7*ln(3300-O5) -> -47.28143 | U5: =-7*ln(3300-R5) -> -49.094367 | V5: =if(N5=1,1/(1+exp(U5-T5)),"") -> 0.85971655 | W5: =power((3300-O5)/200,1.6) -> 10.276669 | X5: =ln(1+exp((2300-O5)/80))/5 -> 0.031276972 | Y5: =if(N5=1,(W5*(S5-V5))*'Säännöt ja ohjeet'!$B$54+X5,"") -> 2.9145702 | Z5: =-(S5-1) -> 0 | AA5: =1-V5 -> 0.14028345 | AB5: =power((3300-P5)/200,1.6) -> 26.793335 | AC5: =ln(1+exp((2300-P5)/80))/5 -> 1.4039715 | AD5: =if(N5=1,(AB5*(Z5-AA5))*'Säännöt ja ohjeet'!$B$54+AC5,"") -> -6.1133516 | AE5: =10*if($E5=B5,1,-1)+min(10,rounddown((P5-O5)/50,0)-2*$D5*sign(P5-O5))+1 -> 7 | AF5: =10*if($E5=C5,1,-1)+min(10,rounddown((O5-P5)/50,0)-2*$D5*sign(O5-P5))+1 -> -5 | AI5: =if($B5=AI$3,AI4+$Y5,if($C5=AI$3,AI4+$AD5,AI4)) -> 1947.9562 | AJ5: =if($B5=AJ$3,AJ4+$Y5,if($C5=AJ$3,AJ4+$AD5,AJ4)) -> 1732.3696 | AK5: =if($B5=AK$3,AK4+$Y5,if($C5=AK$3,AK4+$AD5,AK4)) -> 2445.0125 | AL5: =if($B5=AL$3,AL4+$Y5,if($C5=AL$3,AL4+$AD5,AL4)) -> 1676.0117 | AM5: =if($B5=AM$3,AM4+$Y5,if($C5=AM$3,AM4+$AD5,AM4)) -> 1804.0721 | AN5: =if($B5=AN$3,AN4+$Y5,if($C5=AN$3,AN4+$AD5,AN4)) -> 2324.4055 | AO5: =if($B5=AO$3,AO4+$Y5,if($C5=AO$3,AO4+$AD5,AO4)) -> 2286.3278 | AP5: =if($B5=AP$3,AP4+$Y5,if($C5=AP$3,AP4+$AD5,AP4)) -> 1646.0151 | ... ED5: =if($B5=ED$3,ED4+$Y5,if($C5=ED$3,ED4+$AD5,ED4)) -> #N/A | EE5: =sum(iferror(AI5:BH5,0))/count(AI5:BH5) -> 1647.6443
A6: uses the af | B6: Janne L | C6: Ilia | D6: 0 | E6: Ilia | F6: 46106 | H6: =if(countblank(B6:E6)<4,TRUE,FALSE) -> TRUE | I6: =if(iferror(match(B6,'Osallistujat ja seuranta'!C:C,0),0)>0,TRUE,FALSE) -> TRUE | J6: =if(iferror(match(C6,'Osallistujat ja seuranta'!C:C,0),0)>0,TRUE,FALSE) -> TRUE | K6: =not(B6=C6) -> TRUE | L6: =or(E6=B6,E6=C6) -> TRUE | M6: =countblank(B6:E6)=0 -> TRUE | N6: =if(and(I6:M6),1,if(H6,0,"")) -> 1 | O6: =if(N6=1,index(5:5,1,match(B6,$3:$3,0)),"") -> 1091 | P6: =if(N6=1,index(5:5,1,match(C6,$3:$3,0)),"") -> 800 | Q6: =if(N6=1,O6-(P6+D6*100-if(D6>0,50,0))*N6,"") -> 291 | R6: =if(N6=1,P6+D6*100-if(D6>0,50,0),"") -> 800 | S6: =if(E6=B6,1,0) -> 0 | T6: =-7*ln(3300-O6) -> -53.902066 | U6: =-7*ln(3300-R6) -> -54.768322 | V6: =if(N6=1,1/(1+exp(U6-T6)),"") -> 0.70396598 | W6: =power((3300-O6)/200,1.6) -> 46.672939 | X6: =ln(1+exp((2300-O6)/80))/5 -> 3.0225001 | Y6: =if(N6=1,(W6*(S6-V6))*'Säännöt ja ohjeet'!$B$54+X6,"") -> -62.689823 | Z6: =-(S6-1) -> 1 | AA6: =1-V6 -> 0.29603402 | AB6: =power((3300-P6)/200,1.6) -> 56.892631 | AC6: =ln(1+exp((2300-P6)/80))/5 -> 3.75 | AD6: =if(N6=1,(AB6*(Z6-AA6))*'Säännöt ja ohjeet'!$B$54+AC6,"") -> 83.850954 | AE6: =10*if($E6=B6,1,-1)+min(10,rounddown((P6-O6)/50,0)-2*$D6*sign(P6-O6))+1 -> -14 | AF6: =10*if($E6=C6,1,-1)+min(10,rounddown((O6-P6)/50,0)-2*$D6*sign(O6-P6))+1 -> 16 | AI6: =if($B6=AI$3,AI5+$Y6,if($C6=AI$3,AI5+$AD6,AI5)) -> 1947.9562 | AJ6: =if($B6=AJ$3,AJ5+$Y6,if($C6=AJ$3,AJ5+$AD6,AJ5)) -> 1732.3696 | AK6: =if($B6=AK$3,AK5+$Y6,if($C6=AK$3,AK5+$AD6,AK5)) -> 2445.0125 | AL6: =if($B6=AL$3,AL5+$Y6,if($C6=AL$3,AL5+$AD6,AL5)) -> 1676.0117 | AM6: =if($B6=AM$3,AM5+$Y6,if($C6=AM$3,AM5+$AD6,AM5)) -> 1804.0721 | AN6: =if($B6=AN$3,AN5+$Y6,if($C6=AN$3,AN5+$AD6,AN5)) -> 2324.4055 | AO6: =if($B6=AO$3,AO5+$Y6,if($C6=AO$3,AO5+$AD6,AO5)) -> 2286.3278 | AP6: =if($B6=AP$3,AP5+$Y6,if($C6=AP$3,AP5+$AD6,AP5)) -> 1646.0151 | ... ED6: =if($B6=ED$3,ED5+$Y6,if($C6=ED$3,ED5+$AD6,ED5)) -> #N/A | EE6: =sum(iferror(AI6:BH6,0))/count(AI6:BH6) -> 1648.652
B7: Olli | C7: Jussa | D7: 4 | E7: Olli | F7: 46108 | H7: =if(countblank(B7:E7)<4,TRUE,FALSE) -> TRUE | I7: =if(iferror(match(B7,'Osallistujat ja seuranta'!C:C,0),0)>0,TRUE,FALSE) -> TRUE | J7: =if(iferror(match(C7,'Osallistujat ja seuranta'!C:C,0),0)>0,TRUE,FALSE) -> TRUE | K7: =not(B7=C7) -> TRUE | L7: =or(E7=B7,E7=C7) -> TRUE | M7: =countblank(B7:E7)=0 -> TRUE | N7: =if(and(I7:M7),1,if(H7,0,"")) -> 1 | O7: =if(N7=1,index(6:6,1,match(B7,$3:$3,0)),"") -> 2445.0125 | P7: =if(N7=1,index(6:6,1,match(C7,$3:$3,0)),"") -> 1947.9562 | Q7: =if(N7=1,O7-(P7+D7*100-if(D7>0,50,0))*N7,"") -> 147.05634 | R7: =if(N7=1,P7+D7*100-if(D7>0,50,0),"") -> 2297.9562 | S7: =if(E7=B7,1,0) -> 1 | T7: =-7*ln(3300-O7) -> -47.257608 | U7: =-7*ln(3300-R7) -> -48.368579 | V7: =if(N7=1,1/(1+exp(U7-T7)),"") -> 0.75231014 | W7: =power((3300-O7)/200,1.6) -> 10.220865 | X7: =ln(1+exp((2300-O7)/80))/5 -> 0.030238409 | Y7: =if(N7=1,(W7*(S7-V7))*'Säännöt ja ohjeet'!$B$54+X7,"") -> 5.0934475 | Z7: =-(S7-1) -> 0 | AA7: =1-V7 -> 0.24768986 | AB7: =power((3300-P7)/200,1.6) -> 21.278316 | AC7: =ln(1+exp((2300-P7)/80))/5 -> 0.8825488 | AD7: =if(N7=1,(AB7*(Z7-AA7))*'Säännöt ja ohjeet'!$B$54+AC7,"") -> -9.6582974 | AE7: =10*if($E7=B7,1,-1)+min(10,rounddown((P7-O7)/50,0)-2*$D7*sign(P7-O7))+1 -> 10 | AF7: =10*if($E7=C7,1,-1)+min(10,rounddown((O7-P7)/50,0)-2*$D7*sign(O7-P7))+1 -> -8 | AI7: =if($B7=AI$3,AI6+$Y7,if($C7=AI$3,AI6+$AD7,AI6)) -> 1938.2979 | AJ7: =if($B7=AJ$3,AJ6+$Y7,if($C7=AJ$3,AJ6+$AD7,AJ6)) -> 1732.3696 | AK7: =if($B7=AK$3,AK6+$Y7,if($C7=AK$3,AK6+$AD7,AK6)) -> 2450.1059 | AL7: =if($B7=AL$3,AL6+$Y7,if($C7=AL$3,AL6+$AD7,AL6)) -> 1676.0117 | AM7: =if($B7=AM$3,AM6+$Y7,if($C7=AM$3,AM6+$AD7,AM6)) -> 1804.0721 | AN7: =if($B7=AN$3,AN6+$Y7,if($C7=AN$3,AN6+$AD7,AN6)) -> 2324.4055 | AO7: =if($B7=AO$3,AO6+$Y7,if($C7=AO$3,AO6+$AD7,AO6)) -> 2286.3278 | AP7: =if($B7=AP$3,AP6+$Y7,if($C7=AP$3,AP6+$AD7,AP6)) -> 1646.0151 | ... ED7: =if($B7=ED$3,ED6+$Y7,if($C7=ED$3,ED6+$AD7,ED6)) -> #N/A | EE7: =sum(iferror(AI7:BH7,0))/count(AI7:BH7) -> 1648.4346
B8: Olli | C8: Janne L | D8: 9 | E8: Olli | F8: 46108 | H8: =if(countblank(B8:E8)<4,TRUE,FALSE) -> TRUE | I8: =if(iferror(match(B8,'Osallistujat ja seuranta'!C:C,0),0)>0,TRUE,FALSE) -> TRUE | J8: =if(iferror(match(C8,'Osallistujat ja seuranta'!C:C,0),0)>0,TRUE,FALSE) -> TRUE | K8: =not(B8=C8) -> TRUE | L8: =or(E8=B8,E8=C8) -> TRUE | M8: =countblank(B8:E8)=0 -> TRUE | N8: =if(and(I8:M8),1,if(H8,0,"")) -> 1 | O8: =if(N8=1,index(7:7,1,match(B8,$3:$3,0)),"") -> 2450.1059 | P8: =if(N8=1,index(7:7,1,match(C8,$3:$3,0)),"") -> 1028.3102 | Q8: =if(N8=1,O8-(P8+D8*100-if(D8>0,50,0))*N8,"") -> 571.79576 | R8: =if(N8=1,P8+D8*100-if(D8>0,50,0),"") -> 1878.3102 | S8: =if(E8=B8,1,0) -> 1 | T8: =-7*ln(3300-O8) -> -47.215782 | U8: =-7*ln(3300-R8) -> -50.81721 | V8: =if(N8=1,1/(1+exp(U8-T8)),"") -> 0.97343996 | W8: =power((3300-O8)/200,1.6) -> 10.123616 | X8: =ln(1+exp((2300-O8)/80))/5 -> 0.028499817 | Y8: =if(N8=1,(W8*(S8-V8))*'Säännöt ja ohjeet'!$B$54+X8,"") -> 0.56626716 | Z8: =-(S8-1) -> 0 | AA8: =1-V8 -> 0.026560041 | AB8: =power((3300-P8)/200,1.6) -> 48.810186 | AC8: =ln(1+exp((2300-P8)/80))/5 -> 3.1792246 | AD8: =if(N8=1,(AB8*(Z8-AA8))*'Säännöt ja ohjeet'!$B$54+AC8,"") -> 0.58642347 | AE8: =10*if($E8=B8,1,-1)+min(10,rounddown((P8-O8)/50,0)-2*$D8*sign(P8-O8))+1 -> 1 | AF8: =10*if($E8=C8,1,-1)+min(10,rounddown((O8-P8)/50,0)-2*$D8*sign(O8-P8))+1 -> 1 | AI8: =if($B8=AI$3,AI7+$Y8,if($C8=AI$3,AI7+$AD8,AI7)) -> 1938.2979 | AJ8: =if($B8=AJ$3,AJ7+$Y8,if($C8=AJ$3,AJ7+$AD8,AJ7)) -> 1732.3696 | AK8: =if($B8=AK$3,AK7+$Y8,if($C8=AK$3,AK7+$AD8,AK7)) -> 2450.6722 | AL8: =if($B8=AL$3,AL7+$Y8,if($C8=AL$3,AL7+$AD8,AL7)) -> 1676.0117 | AM8: =if($B8=AM$3,AM7+$Y8,if($C8=AM$3,AM7+$AD8,AM7)) -> 1804.0721 | AN8: =if($B8=AN$3,AN7+$Y8,if($C8=AN$3,AN7+$AD8,AN7)) -> 2324.4055 | AO8: =if($B8=AO$3,AO7+$Y8,if($C8=AO$3,AO7+$AD8,AO7)) -> 2286.3278 | AP8: =if($B8=AP$3,AP7+$Y8,if($C8=AP$3,AP7+$AD8,AP7)) -> 1646.0151 | ... ED8: =if($B8=ED$3,ED7+$Y8,if($C8=ED$3,ED7+$AD8,ED7)) -> #N/A | EE8: =sum(iferror(AI8:BH8,0))/count(AI8:BH8) -> 1648.4895
B9: Jussa | C9: Janne L | D9: 5 | E9: Jussa | F9: 46109 | H9: =if(countblank(B9:E9)<4,TRUE,FALSE) -> TRUE | I9: =if(iferror(match(B9,'Osallistujat ja seuranta'!C:C,0),0)>0,TRUE,FALSE) -> TRUE | J9: =if(iferror(match(C9,'Osallistujat ja seuranta'!C:C,0),0)>0,TRUE,FALSE) -> TRUE | K9: =not(B9=C9) -> TRUE | L9: =or(E9=B9,E9=C9) -> TRUE | M9: =countblank(B9:E9)=0 -> TRUE | N9: =if(and(I9:M9),1,if(H9,0,"")) -> 1 | O9: =if(N9=1,index(8:8,1,match(B9,$3:$3,0)),"") -> 1938.2979 | P9: =if(N9=1,index(8:8,1,match(C9,$3:$3,0)),"") -> 1028.8966 | Q9: =if(N9=1,O9-(P9+D9*100-if(D9>0,50,0))*N9,"") -> 459.40126 | R9: =if(N9=1,P9+D9*100-if(D9>0,50,0),"") -> 1478.8966 | S9: =if(E9=B9,1,0) -> 1 | T9: =-7*ln(3300-O9) -> -50.515435 | U9: =-7*ln(3300-R9) -> -52.550385 | V9: =if(N9=1,1/(1+exp(U9-T9)),"") -> 0.88441801 | W9: =power((3300-O9)/200,1.6) -> 21.522038 | X9: =ln(1+exp((2300-O9)/80))/5 -> 0.90641864 | Y9: =if(N9=1,(W9*(S9-V9))*'Säännöt ja ohjeet'!$B$54+X9,"") -> 5.8815388 | Z9: =-(S9-1) -> 0 | AA9: =1-V9 -> 0.11558199 | AB9: =power((3300-P9)/200,1.6) -> 48.790027 | AC9: =ln(1+exp((2300-P9)/80))/5 -> 3.1777585 | AD9: =if(N9=1,(AB9*(Z9-AA9))*'Säännöt ja ohjeet'!$B$54+AC9,"") -> -8.1007387 | AE9: =10*if($E9=B9,1,-1)+min(10,rounddown((P9-O9)/50,0)-2*$D9*sign(P9-O9))+1 -> 3 | AF9: =10*if($E9=C9,1,-1)+min(10,rounddown((O9-P9)/50,0)-2*$D9*sign(O9-P9))+1 -> -1 | AI9: =if($B9=AI$3,AI8+$Y9,if($C9=AI$3,AI8+$AD9,AI8)) -> 1944.1794 | AJ9: =if($B9=AJ$3,AJ8+$Y9,if($C9=AJ$3,AJ8+$AD9,AJ8)) -> 1732.3696 | AK9: =if($B9=AK$3,AK8+$Y9,if($C9=AK$3,AK8+$AD9,AK8)) -> 2450.6722 | AL9: =if($B9=AL$3,AL8+$Y9,if($C9=AL$3,AL8+$AD9,AL8)) -> 1676.0117 | AM9: =if($B9=AM$3,AM8+$Y9,if($C9=AM$3,AM8+$AD9,AM8)) -> 1804.0721 | AN9: =if($B9=AN$3,AN8+$Y9,if($C9=AN$3,AN8+$AD9,AN8)) -> 2324.4055 | AO9: =if($B9=AO$3,AO8+$Y9,if($C9=AO$3,AO8+$AD9,AO8)) -> 2286.3278 | AP9: =if($B9=AP$3,AP8+$Y9,if($C9=AP$3,AP8+$AD9,AP8)) -> 1646.0151 | ... ED9: =if($B9=ED$3,ED8+$Y9,if($C9=ED$3,ED8+$AD9,ED8)) -> #N/A | EE9: =sum(iferror(AI9:BH9,0))/count(AI9:BH9) -> 1648.3838
B10: Olli | C10: Janne L | D10: 9 | E10: Olli | F10: 46109 | H10: =if(countblank(B10:E10)<4,TRUE,FALSE) -> TRUE | I10: =if(iferror(match(B10,'Osallistujat ja seuranta'!C:C,0),0)>0,TRUE,FALSE) -> TRUE | J10: =if(iferror(match(C10,'Osallistujat ja seuranta'!C:C,0),0)>0,TRUE,FALSE) -> TRUE | K10: =not(B10=C10) -> TRUE | L10: =or(E10=B10,E10=C10) -> TRUE | M10: =countblank(B10:E10)=0 -> TRUE | N10: =if(and(I10:M10),1,if(H10,0,"")) -> 1 | O10: =if(N10=1,index(9:9,1,match(B10,$3:$3,0)),"") -> 2450.6722 | P10: =if(N10=1,index(9:9,1,match(C10,$3:$3,0)),"") -> 1020.7959 | Q10: =if(N10=1,O10-(P10+D10*100-if(D10>0,50,0))*N10,"") -> 579.87634 | R10: =if(N10=1,P10+D10*100-if(D10>0,50,0),"") -> 1870.7959 | S10: =if(E10=B10,1,0) -> 1 | T10: =-7*ln(3300-O10) -> -47.211116 | U10: =-7*ln(3300-R10) -> -50.854111 | V10: =if(N10=1,1/(1+exp(U10-T10)),"") -> 0.97449375 | W10: =power((3300-O10)/200,1.6) -> 10.112826 | X10: =ln(1+exp((2300-O10)/80))/5 -> 0.028312375 | Y10: =if(N10=1,(W10*(S10-V10))*'Säännöt ja ohjeet'!$B$54+X10,"") -> 0.54419286 | Z10: =-(S10-1) -> 0 | AA10: =1-V10 -> 0.025506247 | AB10: =power((3300-P10)/200,1.6) -> 49.068769 | AC10: =ln(1+exp((2300-P10)/80))/5 -> 3.1980104 | AD10: =if(N10=1,(AB10*(Z10-AA10))*'Säännöt ja ohjeet'!$B$54+AC10,"") -> 0.69489007 | AE10: =10*if($E10=B10,1,-1)+min(10,rounddown((P10-O10)/50,0)-2*$D10*sign(P10-O10))+1 -> 1 | AF10: =10*if($E10=C10,1,-1)+min(10,rounddown((O10-P10)/50,0)-2*$D10*sign(O10-P10))+1 -> 1 | AI10: =if($B10=AI$3,AI9+$Y10,if($C10=AI$3,AI9+$AD10,AI9)) -> 1944.1794 | AJ10: =if($B10=AJ$3,AJ9+$Y10,if($C10=AJ$3,AJ9+$AD10,AJ9)) -> 1732.3696 | AK10: =if($B10=AK$3,AK9+$Y10,if($C10=AK$3,AK9+$AD10,AK9)) -> 2451.2164 | AL10: =if($B10=AL$3,AL9+$Y10,if($C10=AL$3,AL9+$AD10,AL9)) -> 1676.0117 | AM10: =if($B10=AM$3,AM9+$Y10,if($C10=AM$3,AM9+$AD10,AM9)) -> 1804.0721 | AN10: =if($B10=AN$3,AN9+$Y10,if($C10=AN$3,AN9+$AD10,AN9)) -> 2324.4055 | AO10: =if($B10=AO$3,AO9+$Y10,if($C10=AO$3,AO9+$AD10,AO9)) -> 2286.3278 | AP10: =if($B10=AP$3,AP9+$Y10,if($C10=AP$3,AP9+$AD10,AP9)) -> 1646.0151 | ... ED10: =if($B10=ED$3,ED9+$Y10,if($C10=ED$3,ED9+$AD10,ED9)) -> #N/A | EE10: =sum(iferror(AI10:BH10,0))/count(AI10:BH10) -> 1648.4428
B11: Jussa | C11: Janne L | D11: 5 | E11: Jussa | F11: 46110 | H11: =if(countblank(B11:E11)<4,TRUE,FALSE) -> TRUE | I11: =if(iferror(match(B11,'Osallistujat ja seuranta'!C:C,0),0)>0,TRUE,FALSE) -> TRUE | J11: =if(iferror(match(C11,'Osallistujat ja seuranta'!C:C,0),0)>0,TRUE,FALSE) -> TRUE | K11: =not(B11=C11) -> TRUE | L11: =or(E11=B11,E11=C11) -> TRUE | M11: =countblank(B11:E11)=0 -> TRUE | N11: =if(and(I11:M11),1,if(H11,0,"")) -> 1 | O11: =if(N11=1,index(10:10,1,match(B11,$3:$3,0)),"") -> 1944.1794 | P11: =if(N11=1,index(10:10,1,match(C11,$3:$3,0)),"") -> 1021.4908 | Q11: =if(N11=1,O11-(P11+D11*100-if(D11>0,50,0))*N11,"") -> 472.68865 | R11: =if(N11=1,P11+D11*100-if(D11>0,50,0),"") -> 1471.4908 | S11: =if(E11=B11,1,0) -> 1 | T11: =-7*ln(3300-O11) -> -50.485135 | U11: =-7*ln(3300-R11) -> -52.578794 | V11: =if(N11=1,1/(1+exp(U11-T11)),"") -> 0.89028533 | W11: =power((3300-O11)/200,1.6) -> 21.373496 | X11: =ln(1+exp((2300-O11)/80))/5 -> 0.89187887 | Y11: =if(N11=1,(W11*(S11-V11))*'Säännöt ja ohjeet'!$B$54+X11,"") -> 5.581851 | Z11: =-(S11-1) -> 0 | AA11: =1-V11 -> 0.10971467 | AB11: =power((3300-P11)/200,1.6) -> 49.044835 | AC11: =ln(1+exp((2300-P11)/80))/5 -> 3.1962731 | AD11: =if(N11=1,(AB11*(Z11-AA11))*'Säännöt ja ohjeet'!$B$54+AC11,"") -> -7.5656025 | AE11: =10*if($E11=B11,1,-1)+min(10,rounddown((P11-O11)/50,0)-2*$D11*sign(P11-O11))+1 -> 3 | AF11: =10*if($E11=C11,1,-1)+min(10,rounddown((O11-P11)/50,0)-2*$D11*sign(O11-P11))+1 -> -1 | AI11: =if($B11=AI$3,AI10+$Y11,if($C11=AI$3,AI10+$AD11,AI10)) -> 1949.7612 | AJ11: =if($B11=AJ$3,AJ10+$Y11,if($C11=AJ$3,AJ10+$AD11,AJ10)) -> 1732.3696 | AK11: =if($B11=AK$3,AK10+$Y11,if($C11=AK$3,AK10+$AD11,AK10)) -> 2451.2164 | AL11: =if($B11=AL$3,AL10+$Y11,if($C11=AL$3,AL10+$AD11,AL10)) -> 1676.0117 | AM11: =if($B11=AM$3,AM10+$Y11,if($C11=AM$3,AM10+$AD11,AM10)) -> 1804.0721 | AN11: =if($B11=AN$3,AN10+$Y11,if($C11=AN$3,AN10+$AD11,AN10)) -> 2324.4055 | AO11: =if($B11=AO$3,AO10+$Y11,if($C11=AO$3,AO10+$AD11,AO10)) -> 2286.3278 | AP11: =if($B11=AP$3,AP10+$Y11,if($C11=AP$3,AP10+$AD11,AP10)) -> 1646.0151 | ... ED11: =if($B11=ED$3,ED10+$Y11,if($C11=ED$3,ED10+$AD11,ED10)) -> #N/A | EE11: =sum(iferror(AI11:BH11,0))/count(AI11:BH11) -> 1648.3483
B12: Olli | C12: Janne L | D12: 9 | E12: Janne L | F12: 46110 | H12: =if(countblank(B12:E12)<4,TRUE,FALSE) -> TRUE | I12: =if(iferror(match(B12,'Osallistujat ja seuranta'!C:C,0),0)>0,TRUE,FALSE) -> TRUE | J12: =if(iferror(match(C12,'Osallistujat ja seuranta'!C:C,0),0)>0,TRUE,FALSE) -> TRUE | K12: =not(B12=C12) -> TRUE | L12: =or(E12=B12,E12=C12) -> TRUE | M12: =countblank(B12:E12)=0 -> TRUE | N12: =if(and(I12:M12),1,if(H12,0,"")) -> 1 | O12: =if(N12=1,index(11:11,1,match(B12,$3:$3,0)),"") -> 2451.2164 | P12: =if(N12=1,index(11:11,1,match(C12,$3:$3,0)),"") -> 1013.9251 | Q12: =if(N12=1,O12-(P12+D12*100-if(D12>0,50,0))*N12,"") -> 587.29125 | R12: =if(N12=1,P12+D12*100-if(D12>0,50,0),"") -> 1863.9251 | S12: =if(E12=B12,1,0) -> 0 | T12: =-7*ln(3300-O12) -> -47.20663 | U12: =-7*ln(3300-R12) -> -50.887682 | V12: =if(N12=1,1/(1+exp(U12-T12)),"") -> 0.97542281 | W12: =power((3300-O12)/200,1.6) -> 10.102461 | X12: =ln(1+exp((2300-O12)/80))/5 -> 0.028133323 | Y12: =if(N12=1,(W12*(S12-V12))*'Säännöt ja ohjeet'!$B$54+X12,"") -> -19.680208 | Z12: =-(S12-1) -> 1 | AA12: =1-V12 -> 0.02457719 | AB12: =power((3300-P12)/200,1.6) -> 49.305654 | AC12: =ln(1+exp((2300-P12)/80))/5 -> 3.2151871 | AD12: =if(N12=1,(AB12*(Z12-AA12))*'Säännöt ja ohjeet'!$B$54+AC12,"") -> 99.402906 | AE12: =10*if($E12=B12,1,-1)+min(10,rounddown((P12-O12)/50,0)-2*$D12*sign(P12-O12))+1 -> -19 | AF12: =10*if($E12=C12,1,-1)+min(10,rounddown((O12-P12)/50,0)-2*$D12*sign(O12-P12))+1 -> 21 | AI12: =if($B12=AI$3,AI11+$Y12,if($C12=AI$3,AI11+$AD12,AI11)) -> 1949.7612 | AJ12: =if($B12=AJ$3,AJ11+$Y12,if($C12=AJ$3,AJ11+$AD12,AJ11)) -> 1732.3696 | AK12: =if($B12=AK$3,AK11+$Y12,if($C12=AK$3,AK11+$AD12,AK11)) -> 2431.5362 | AL12: =if($B12=AL$3,AL11+$Y12,if($C12=AL$3,AL11+$AD12,AL11)) -> 1676.0117 | AM12: =if($B12=AM$3,AM11+$Y12,if($C12=AM$3,AM11+$AD12,AM11)) -> 1804.0721 | AN12: =if($B12=AN$3,AN11+$Y12,if($C12=AN$3,AN11+$AD12,AN11)) -> 2324.4055 | AO12: =if($B12=AO$3,AO11+$Y12,if($C12=AO$3,AO11+$AD12,AO11)) -> 2286.3278 | AP12: =if($B12=AP$3,AP11+$Y12,if($C12=AP$3,AP11+$AD12,AP11)) -> 1646.0151 | ... ED12: =if($B12=ED$3,ED11+$Y12,if($C12=ED$3,ED11+$AD12,ED11)) -> #N/A | EE12: =sum(iferror(AI12:BH12,0))/count(AI12:BH12) -> 1652.1447
B13: Olli | C13: Jussa | D13: 4 | E13: Olli | F13: 46110 | H13: =if(countblank(B13:E13)<4,TRUE,FALSE) -> TRUE | I13: =if(iferror(match(B13,'Osallistujat ja seuranta'!C:C,0),0)>0,TRUE,FALSE) -> TRUE | J13: =if(iferror(match(C13,'Osallistujat ja seuranta'!C:C,0),0)>0,TRUE,FALSE) -> TRUE | K13: =not(B13=C13) -> TRUE | L13: =or(E13=B13,E13=C13) -> TRUE | M13: =countblank(B13:E13)=0 -> TRUE | N13: =if(and(I13:M13),1,if(H13,0,"")) -> 1 | O13: =if(N13=1,index(12:12,1,match(B13,$3:$3,0)),"") -> 2431.5362 | P13: =if(N13=1,index(12:12,1,match(C13,$3:$3,0)),"") -> 1949.7612 | Q13: =if(N13=1,O13-(P13+D13*100-if(D13>0,50,0))*N13,"") -> 131.77494 | R13: =if(N13=1,P13+D13*100-if(D13>0,50,0),"") -> 2299.7612 | S13: =if(E13=B13,1,0) -> 1 | T13: =-7*ln(3300-O13) -> -47.367081 | U13: =-7*ln(3300-R13) -> -48.355958 | V13: =if(N13=1,1/(1+exp(U13-T13)),"") -> 0.72886598 | W13: =power((3300-O13)/200,1.6) -> 10.479843 | X13: =ln(1+exp((2300-O13)/80))/5 -> 0.035322152 | Y13: =if(N13=1,(W13*(S13-V13))*'Säännöt ja ohjeet'!$B$54+X13,"") -> 5.7182061 | Z13: =-(S13-1) -> 0 | AA13: =1-V13 -> 0.27113402 | AB13: =power((3300-P13)/200,1.6) -> 21.232881 | AC13: =ln(1+exp((2300-P13)/80))/5 -> 0.87809138 | AD13: =if(N13=1,(AB13*(Z13-AA13))*'Säännöt ja ohjeet'!$B$54+AC13,"") -> -10.635821 | AE13: =10*if($E13=B13,1,-1)+min(10,rounddown((P13-O13)/50,0)-2*$D13*sign(P13-O13))+1 -> 10 | AF13: =10*if($E13=C13,1,-1)+min(10,rounddown((O13-P13)/50,0)-2*$D13*sign(O13-P13))+1 -> -8 | AI13: =if($B13=AI$3,AI12+$Y13,if($C13=AI$3,AI12+$AD13,AI12)) -> 1939.1254 | AJ13: =if($B13=AJ$3,AJ12+$Y13,if($C13=AJ$3,AJ12+$AD13,AJ12)) -> 1732.3696 | AK13: =if($B13=AK$3,AK12+$Y13,if($C13=AK$3,AK12+$AD13,AK12)) -> 2437.2544 | AL13: =if($B13=AL$3,AL12+$Y13,if($C13=AL$3,AL12+$AD13,AL12)) -> 1676.0117 | AM13: =if($B13=AM$3,AM12+$Y13,if($C13=AM$3,AM12+$AD13,AM12)) -> 1804.0721 | AN13: =if($B13=AN$3,AN12+$Y13,if($C13=AN$3,AN12+$AD13,AN12)) -> 2324.4055 | AO13: =if($B13=AO$3,AO12+$Y13,if($C13=AO$3,AO12+$AD13,AO12)) -> 2286.3278 | AP13: =if($B13=AP$3,AP12+$Y13,if($C13=AP$3,AP12+$AD13,AP12)) -> 1646.0151 | ... ED13: =if($B13=ED$3,ED12+$Y13,if($C13=ED$3,ED12+$AD13,ED12)) -> #N/A | EE13: =sum(iferror(AI13:BH13,0))/count(AI13:BH13) -> 1651.9105
B14: Teemu | C14: Peitsa | D14: 4 | E14: Peitsa | F14: 46110 | H14: =if(countblank(B14:E14)<4,TRUE,FALSE) -> TRUE | I14: =if(iferror(match(B14,'Osallistujat ja seuranta'!C:C,0),0)>0,TRUE,FALSE) -> TRUE | J14: =if(iferror(match(C14,'Osallistujat ja seuranta'!C:C,0),0)>0,TRUE,FALSE) -> TRUE | K14: =not(B14=C14) -> TRUE | L14: =or(E14=B14,E14=C14) -> TRUE | M14: =countblank(B14:E14)=0 -> TRUE | N14: =if(and(I14:M14),1,if(H14,0,"")) -> 1 | O14: =if(N14=1,index(13:13,1,match(B14,$3:$3,0)),"") -> 2219 | P14: =if(N14=1,index(13:13,1,match(C14,$3:$3,0)),"") -> 1732.3696 | Q14: =if(N14=1,O14-(P14+D14*100-if(D14>0,50,0))*N14,"") -> 136.63039 | R14: =if(N14=1,P14+D14*100-if(D14>0,50,0),"") -> 2082.3696 | S14: =if(E14=B14,1,0) -> 0 | T14: =-7*ln(3300-O14) -> -48.899493 | U14: =-7*ln(3300-R14) -> -49.732634 | V14: =if(N14=1,1/(1+exp(U14-T14)),"") -> 0.69701865 | W14: =power((3300-O14)/200,1.6) -> 14.875553 | X14: =ln(1+exp((2300-O14)/80))/5 -> 0.26448305 | Y14: =if(N14=1,(W14*(S14-V14))*'Säännöt ja ohjeet'!$B$54+X14,"") -> -20.472593 | Z14: =-(S14-1) -> 1 | AA14: =1-V14 -> 0.30298135 | AB14: =power((3300-P14)/200,1.6) -> 26.961366 | AC14: =ln(1+exp((2300-P14)/80))/5 -> 1.4192417 | AD14: =if(N14=1,(AB14*(Z14-AA14))*'Säännöt ja ohjeet'!$B$54+AC14,"") -> 39.004391 | AE14: =10*if($E14=B14,1,-1)+min(10,rounddown((P14-O14)/50,0)-2*$D14*sign(P14-O14))+1 -> -10 | AF14: =10*if($E14=C14,1,-1)+min(10,rounddown((O14-P14)/50,0)-2*$D14*sign(O14-P14))+1 -> 12 | AI14: =if($B14=AI$3,AI13+$Y14,if($C14=AI$3,AI13+$AD14,AI13)) -> 1939.1254 | AJ14: =if($B14=AJ$3,AJ13+$Y14,if($C14=AJ$3,AJ13+$AD14,AJ13)) -> 1771.374 | AK14: =if($B14=AK$3,AK13+$Y14,if($C14=AK$3,AK13+$AD14,AK13)) -> 2437.2544 | AL14: =if($B14=AL$3,AL13+$Y14,if($C14=AL$3,AL13+$AD14,AL13)) -> 1676.0117 | AM14: =if($B14=AM$3,AM13+$Y14,if($C14=AM$3,AM13+$AD14,AM13)) -> 1804.0721 | AN14: =if($B14=AN$3,AN13+$Y14,if($C14=AN$3,AN13+$AD14,AN13)) -> 2324.4055 | AO14: =if($B14=AO$3,AO13+$Y14,if($C14=AO$3,AO13+$AD14,AO13)) -> 2286.3278 | AP14: =if($B14=AP$3,AP13+$Y14,if($C14=AP$3,AP13+$AD14,AP13)) -> 1646.0151 | ... ED14: =if($B14=ED$3,ED13+$Y14,if($C14=ED$3,ED13+$AD14,ED13)) -> #N/A | EE14: =sum(iferror(AI14:BH14,0))/count(AI14:BH14) -> 1652.793
B15: Teemu | C15: Tomi | D15: 1 | E15: Tomi | F15: 46110 | H15: =if(countblank(B15:E15)<4,TRUE,FALSE) -> TRUE | I15: =if(iferror(match(B15,'Osallistujat ja seuranta'!C:C,0),0)>0,TRUE,FALSE) -> TRUE | J15: =if(iferror(match(C15,'Osallistujat ja seuranta'!C:C,0),0)>0,TRUE,FALSE) -> TRUE | K15: =not(B15=C15) -> TRUE | L15: =or(E15=B15,E15=C15) -> TRUE | M15: =countblank(B15:E15)=0 -> TRUE | N15: =if(and(I15:M15),1,if(H15,0,"")) -> 1 | O15: =if(N15=1,index(14:14,1,match(B15,$3:$3,0)),"") -> 2198.5274 | P15: =if(N15=1,index(14:14,1,match(C15,$3:$3,0)),"") -> 2158 | Q15: =if(N15=1,O15-(P15+D15*100-if(D15>0,50,0))*N15,"") -> -9.4725925 | R15: =if(N15=1,P15+D15*100-if(D15>0,50,0),"") -> 2208 | S15: =if(E15=B15,1,0) -> 0 | T15: =-7*ln(3300-O15) -> -49.030823 | U15: =-7*ln(3300-R15) -> -48.970363 | V15: =if(N15=1,1/(1+exp(U15-T15)),"") -> 0.48488963 | W15: =power((3300-O15)/200,1.6) -> 15.328862 | X15: =ln(1+exp((2300-O15)/80))/5 -> 0.30325328 | Y15: =if(N15=1,(W15*(S15-V15))*'Säännöt ja ohjeet'!$B$54+X15,"") -> -14.562359 | Z15: =-(S15-1) -> 1 | AA15: =1-V15 -> 0.51511037 | AB15: =power((3300-P15)/200,1.6) -> 16.241187 | AC15: =ln(1+exp((2300-P15)/80))/5 -> 0.38631243 | AD15: =if(N15=1,(AB15*(Z15-AA15))*'Säännöt ja ohjeet'!$B$54+AC15,"") -> 16.136679 | AE15: =10*if($E15=B15,1,-1)+min(10,rounddown((P15-O15)/50,0)-2*$D15*sign(P15-O15))+1 -> -7 | AF15: =10*if($E15=C15,1,-1)+min(10,rounddown((O15-P15)/50,0)-2*$D15*sign(O15-P15))+1 -> 9 | AI15: =if($B15=AI$3,AI14+$Y15,if($C15=AI$3,AI14+$AD15,AI14)) -> 1939.1254 | AJ15: =if($B15=AJ$3,AJ14+$Y15,if($C15=AJ$3,AJ14+$AD15,AJ14)) -> 1771.374 | AK15: =if($B15=AK$3,AK14+$Y15,if($C15=AK$3,AK14+$AD15,AK14)) -> 2437.2544 | AL15: =if($B15=AL$3,AL14+$Y15,if($C15=AL$3,AL14+$AD15,AL14)) -> 1676.0117 | AM15: =if($B15=AM$3,AM14+$Y15,if($C15=AM$3,AM14+$AD15,AM14)) -> 1804.0721 | AN15: =if($B15=AN$3,AN14+$Y15,if($C15=AN$3,AN14+$AD15,AN14)) -> 2324.4055 | AO15: =if($B15=AO$3,AO14+$Y15,if($C15=AO$3,AO14+$AD15,AO14)) -> 2286.3278 | AP15: =if($B15=AP$3,AP14+$Y15,if($C15=AP$3,AP14+$AD15,AP14)) -> 1646.0151 | ... ED15: =if($B15=ED$3,ED14+$Y15,if($C15=ED$3,ED14+$AD15,ED14)) -> #N/A | EE15: =sum(iferror(AI15:BH15,0))/count(AI15:BH15) -> 1652.8679
B16: Tomi | C16: Peitsa | D16: 3 | E16: Peitsa | F16: 46110 | H16: =if(countblank(B16:E16)<4,TRUE,FALSE) -> TRUE | I16: =if(iferror(match(B16,'Osallistujat ja seuranta'!C:C,0),0)>0,TRUE,FALSE) -> TRUE | J16: =if(iferror(match(C16,'Osallistujat ja seuranta'!C:C,0),0)>0,TRUE,FALSE) -> TRUE | K16: =not(B16=C16) -> TRUE | L16: =or(E16=B16,E16=C16) -> TRUE | M16: =countblank(B16:E16)=0 -> TRUE | N16: =if(and(I16:M16),1,if(H16,0,"")) -> 1 | O16: =if(N16=1,index(15:15,1,match(B16,$3:$3,0)),"") -> 2174.1367 | P16: =if(N16=1,index(15:15,1,match(C16,$3:$3,0)),"") -> 1771.374 | Q16: =if(N16=1,O16-(P16+D16*100-if(D16>0,50,0))*N16,"") -> 152.76268 | R16: =if(N16=1,P16+D16*100-if(D16>0,50,0),"") -> 2021.374 | S16: =if(E16=B16,1,0) -> 0 | T16: =-7*ln(3300-O16) -> -49.184138 | U16: =-7*ln(3300-R16) -> -50.074789 | V16: =if(N16=1,1/(1+exp(U16-T16)),"") -> 0.7090246 | W16: =power((3300-O16)/200,1.6) -> 15.875561 | X16: =ln(1+exp((2300-O16)/80))/5 -> 0.35234579 | Y16: =if(N16=1,(W16*(S16-V16))*'Säännöt ja ohjeet'!$B$54+X16,"") -> -22.159981 | Z16: =-(S16-1) -> 1 | AA16: =1-V16 -> 0.2909754 | AB16: =power((3300-P16)/200,1.6) -> 25.896078 | AC16: =ln(1+exp((2300-P16)/80))/5 -> 1.3218348 | AD16: =if(N16=1,(AB16*(Z16-AA16))*'Säännöt ja ohjeet'!$B$54+AC16,"") -> 38.043747 | AE16: =10*if($E16=B16,1,-1)+min(10,rounddown((P16-O16)/50,0)-2*$D16*sign(P16-O16))+1 -> -11 | AF16: =10*if($E16=C16,1,-1)+min(10,rounddown((O16-P16)/50,0)-2*$D16*sign(O16-P16))+1 -> 13 | AI16: =if($B16=AI$3,AI15+$Y16,if($C16=AI$3,AI15+$AD16,AI15)) -> 1939.1254 | AJ16: =if($B16=AJ$3,AJ15+$Y16,if($C16=AJ$3,AJ15+$AD16,AJ15)) -> 1809.4177 | AK16: =if($B16=AK$3,AK15+$Y16,if($C16=AK$3,AK15+$AD16,AK15)) -> 2437.2544 | AL16: =if($B16=AL$3,AL15+$Y16,if($C16=AL$3,AL15+$AD16,AL15)) -> 1676.0117 | AM16: =if($B16=AM$3,AM15+$Y16,if($C16=AM$3,AM15+$AD16,AM15)) -> 1804.0721 | AN16: =if($B16=AN$3,AN15+$Y16,if($C16=AN$3,AN15+$AD16,AN15)) -> 2324.4055 | AO16: =if($B16=AO$3,AO15+$Y16,if($C16=AO$3,AO15+$AD16,AO15)) -> 2286.3278 | AP16: =if($B16=AP$3,AP15+$Y16,if($C16=AP$3,AP15+$AD16,AP15)) -> 1646.0151 | ... ED16: =if($B16=ED$3,ED15+$Y16,if($C16=ED$3,ED15+$AD16,ED15)) -> #N/A | EE16: =sum(iferror(AI16:BH16,0))/count(AI16:BH16) -> 1653.6243
B17: Jussa | C17: Peitsa | D17: 0 | E17: Peitsa | F17: 46113 | H17: =if(countblank(B17:E17)<4,TRUE,FALSE) -> TRUE | I17: =if(iferror(match(B17,'Osallistujat ja seuranta'!C:C,0),0)>0,TRUE,FALSE) -> TRUE | J17: =if(iferror(match(C17,'Osallistujat ja seuranta'!C:C,0),0)>0,TRUE,FALSE) -> TRUE | K17: =not(B17=C17) -> TRUE | L17: =or(E17=B17,E17=C17) -> TRUE | M17: =countblank(B17:E17)=0 -> TRUE | N17: =if(and(I17:M17),1,if(H17,0,"")) -> 1 | O17: =if(N17=1,index(16:16,1,match(B17,$3:$3,0)),"") -> 1939.1254 | P17: =if(N17=1,index(16:16,1,match(C17,$3:$3,0)),"") -> 1809.4177 | Q17: =if(N17=1,O17-(P17+D17*100-if(D17>0,50,0))*N17,"") -> 129.70768 | R17: =if(N17=1,P17+D17*100-if(D17>0,50,0),"") -> 1809.4177 | S17: =if(E17=B17,1,0) -> 0 | T17: =-7*ln(3300-O17) -> -50.51118 | U17: =-7*ln(3300-R17) -> -51.148455 | V17: =if(N17=1,1/(1+exp(U17-T17)),"") -> 0.65413717 | W17: =power((3300-O17)/200,1.6) -> 21.501114 | X17: =ln(1+exp((2300-O17)/80))/5 -> 0.90437209 | Y17: =if(N17=1,(W17*(S17-V17))*'Säännöt ja ohjeet'!$B$54+X17,"") -> -27.224984 | Z17: =-(S17-1) -> 1 | AA17: =1-V17 -> 0.34586283 | AB17: =power((3300-P17)/200,1.6) -> 24.872619 | AC17: =ln(1+exp((2300-P17)/80))/5 -> 1.2268895 | AD17: =if(N17=1,(AB17*(Z17-AA17))*'Säännöt ja ohjeet'!$B$54+AC17,"") -> 33.767099 | AE17: =10*if($E17=B17,1,-1)+min(10,rounddown((P17-O17)/50,0)-2*$D17*sign(P17-O17))+1 -> -11 | AF17: =10*if($E17=C17,1,-1)+min(10,rounddown((O17-P17)/50,0)-2*$D17*sign(O17-P17))+1 -> 13 | AI17: =if($B17=AI$3,AI16+$Y17,if($C17=AI$3,AI16+$AD17,AI16)) -> 1911.9004 | AJ17: =if($B17=AJ$3,AJ16+$Y17,if($C17=AJ$3,AJ16+$AD17,AJ16)) -> 1843.1848 | AK17: =if($B17=AK$3,AK16+$Y17,if($C17=AK$3,AK16+$AD17,AK16)) -> 2437.2544 | AL17: =if($B17=AL$3,AL16+$Y17,if($C17=AL$3,AL16+$AD17,AL16)) -> 1676.0117 | AM17: =if($B17=AM$3,AM16+$Y17,if($C17=AM$3,AM16+$AD17,AM16)) -> 1804.0721 | AN17: =if($B17=AN$3,AN16+$Y17,if($C17=AN$3,AN16+$AD17,AN16)) -> 2324.4055 | AO17: =if($B17=AO$3,AO16+$Y17,if($C17=AO$3,AO16+$AD17,AO16)) -> 2286.3278 | AP17: =if($B17=AP$3,AP16+$Y17,if($C17=AP$3,AP16+$AD17,AP16)) -> 1646.0151 | ... ED17: =if($B17=ED$3,ED16+$Y17,if($C17=ED$3,ED16+$AD17,ED16)) -> #N/A | EE17: =sum(iferror(AI17:BH17,0))/count(AI17:BH17) -> 1653.9358
B18: Jussa | C18: Peitsa | D18: 0 | E18: Peitsa | F18: 46113 | H18: =if(countblank(B18:E18)<4,TRUE,FALSE) -> TRUE | I18: =if(iferror(match(B18,'Osallistujat ja seuranta'!C:C,0),0)>0,TRUE,FALSE) -> TRUE | J18: =if(iferror(match(C18,'Osallistujat ja seuranta'!C:C,0),0)>0,TRUE,FALSE) -> TRUE | K18: =not(B18=C18) -> TRUE | L18: =or(E18=B18,E18=C18) -> TRUE | M18: =countblank(B18:E18)=0 -> TRUE | N18: =if(and(I18:M18),1,if(H18,0,"")) -> 1 | O18: =if(N18=1,index(17:17,1,match(B18,$3:$3,0)),"") -> 1911.9004 | P18: =if(N18=1,index(17:17,1,match(C18,$3:$3,0)),"") -> 1843.1848 | Q18: =if(N18=1,O18-(P18+D18*100-if(D18>0,50,0))*N18,"") -> 68.715599 | R18: =if(N18=1,P18+D18*100-if(D18>0,50,0),"") -> 1843.1848 | S18: =if(E18=B18,1,0) -> 0 | T18: =-7*ln(3300-O18) -> -50.649836 | U18: =-7*ln(3300-R18) -> -50.988056 | V18: =if(N18=1,1/(1+exp(U18-T18)),"") -> 0.58375794 | W18: =power((3300-O18)/200,1.6) -> 22.193459 | X18: =ln(1+exp((2300-O18)/80))/5 -> 0.97180654 | Y18: =if(N18=1,(W18*(S18-V18))*'Säännöt ja ohjeet'!$B$54+X18,"") -> -24.939409 | Z18: =-(S18-1) -> 1 | AA18: =1-V18 -> 0.41624206 | AB18: =power((3300-P18)/200,1.6) -> 23.977237 | AC18: =ln(1+exp((2300-P18)/80))/5 -> 1.1426992 | AD18: =if(N18=1,(AB18*(Z18-AA18))*'Säännöt ja ohjeet'!$B$54+AC18,"") -> 29.136504 | AE18: =10*if($E18=B18,1,-1)+min(10,rounddown((P18-O18)/50,0)-2*$D18*sign(P18-O18))+1 -> -10 | AF18: =10*if($E18=C18,1,-1)+min(10,rounddown((O18-P18)/50,0)-2*$D18*sign(O18-P18))+1 -> 12 | AI18: =if($B18=AI$3,AI17+$Y18,if($C18=AI$3,AI17+$AD18,AI17)) -> 1886.961 | AJ18: =if($B18=AJ$3,AJ17+$Y18,if($C18=AJ$3,AJ17+$AD18,AJ17)) -> 1872.3213 | AK18: =if($B18=AK$3,AK17+$Y18,if($C18=AK$3,AK17+$AD18,AK17)) -> 2437.2544 | AL18: =if($B18=AL$3,AL17+$Y18,if($C18=AL$3,AL17+$AD18,AL17)) -> 1676.0117 | AM18: =if($B18=AM$3,AM17+$Y18,if($C18=AM$3,AM17+$AD18,AM17)) -> 1804.0721 | AN18: =if($B18=AN$3,AN17+$Y18,if($C18=AN$3,AN17+$AD18,AN17)) -> 2324.4055 | AO18: =if($B18=AO$3,AO17+$Y18,if($C18=AO$3,AO17+$AD18,AO17)) -> 2286.3278 | AP18: =if($B18=AP$3,AP17+$Y18,if($C18=AP$3,AP17+$AD18,AP17)) -> 1646.0151 | ... ED18: =if($B18=ED$3,ED17+$Y18,if($C18=ED$3,ED17+$AD18,ED17)) -> #N/A | EE18: =sum(iferror(AI18:BH18,0))/count(AI18:BH18) -> 1654.1357
B19: Kulkija | C19: Janne L | D19: 0 | E19: Kulkija | F19: 46113 | H19: =if(countblank(B19:E19)<4,TRUE,FALSE) -> TRUE | I19: =if(iferror(match(B19,'Osallistujat ja seuranta'!C:C,0),0)>0,TRUE,FALSE) -> TRUE | J19: =if(iferror(match(C19,'Osallistujat ja seuranta'!C:C,0),0)>0,TRUE,FALSE) -> TRUE | K19: =not(B19=C19) -> TRUE | L19: =or(E19=B19,E19=C19) -> TRUE | M19: =countblank(B19:E19)=0 -> TRUE | N19: =if(and(I19:M19),1,if(H19,0,"")) -> 1 | O19: =if(N19=1,index(18:18,1,match(B19,$3:$3,0)),"") -> 1295.9892 | P19: =if(N19=1,index(18:18,1,match(C19,$3:$3,0)),"") -> 1113.3281 | Q19: =if(N19=1,O19-(P19+D19*100-if(D19>0,50,0))*N19,"") -> 182.66114 | R19: =if(N19=1,P19+D19*100-if(D19>0,50,0),"") -> 1113.3281 | S19: =if(E19=B19,1,0) -> 1 | T19: =-7*ln(3300-O19) -> -53.220341 | U19: =-7*ln(3300-R19) -> -53.830952 | V19: =if(N19=1,1/(1+exp(U19-T19)),"") -> 0.64808019 | W19: =power((3300-O19)/200,1.6) -> 39.938532 | X19: =ln(1+exp((2300-O19)/80))/5 -> 2.5100277 | Y19: =if(N19=1,(W19*(S19-V19))*'Säännöt ja ohjeet'!$B$54+X19,"") -> 30.620349 | Z19: =-(S19-1) -> 0 | AA19: =1-V19 -> 0.35191981 | AB19: =power((3300-P19)/200,1.6) -> 45.920417 | AC19: =ln(1+exp((2300-P19)/80))/5 -> 2.9666799 | AD19: =if(N19=1,(AB19*(Z19-AA19))*'Säännöt ja ohjeet'!$B$54+AC19,"") -> -29.353929 | AE19: =10*if($E19=B19,1,-1)+min(10,rounddown((P19-O19)/50,0)-2*$D19*sign(P19-O19))+1 -> 8 | AF19: =10*if($E19=C19,1,-1)+min(10,rounddown((O19-P19)/50,0)-2*$D19*sign(O19-P19))+1 -> -6 | AI19: =if($B19=AI$3,AI18+$Y19,if($C19=AI$3,AI18+$AD19,AI18)) -> 1886.961 | AJ19: =if($B19=AJ$3,AJ18+$Y19,if($C19=AJ$3,AJ18+$AD19,AJ18)) -> 1872.3213 | AK19: =if($B19=AK$3,AK18+$Y19,if($C19=AK$3,AK18+$AD19,AK18)) -> 2437.2544 | AL19: =if($B19=AL$3,AL18+$Y19,if($C19=AL$3,AL18+$AD19,AL18)) -> 1676.0117 | AM19: =if($B19=AM$3,AM18+$Y19,if($C19=AM$3,AM18+$AD19,AM18)) -> 1804.0721 | AN19: =if($B19=AN$3,AN18+$Y19,if($C19=AN$3,AN18+$AD19,AN18)) -> 2324.4055 | AO19: =if($B19=AO$3,AO18+$Y19,if($C19=AO$3,AO18+$AD19,AO18)) -> 2286.3278 | AP19: =if($B19=AP$3,AP18+$Y19,if($C19=AP$3,AP18+$AD19,AP18)) -> 1646.0151 | ... ED19: =if($B19=ED$3,ED18+$Y19,if($C19=ED$3,ED18+$AD19,ED18)) -> #N/A | EE19: =sum(iferror(AI19:BH19,0))/count(AI19:BH19) -> 1654.196
B20: Kulkija | C20: Janne L | D20: 0 | E20: Kulkija | F20: 46113 | H20: =if(countblank(B20:E20)<4,TRUE,FALSE) -> TRUE | I20: =if(iferror(match(B20,'Osallistujat ja seuranta'!C:C,0),0)>0,TRUE,FALSE) -> TRUE | J20: =if(iferror(match(C20,'Osallistujat ja seuranta'!C:C,0),0)>0,TRUE,FALSE) -> TRUE | K20: =not(B20=C20) -> TRUE | L20: =or(E20=B20,E20=C20) -> TRUE | M20: =countblank(B20:E20)=0 -> TRUE | N20: =if(and(I20:M20),1,if(H20,0,"")) -> 1 | O20: =if(N20=1,index(19:19,1,match(B20,$3:$3,0)),"") -> 1326.6095 | P20: =if(N20=1,index(19:19,1,match(C20,$3:$3,0)),"") -> 1083.9741 | Q20: =if(N20=1,O20-(P20+D20*100-if(D20>0,50,0))*N20,"") -> 242.63542 | R20: =if(N20=1,P20+D20*100-if(D20>0,50,0),"") -> 1083.9741 | S20: =if(E20=B20,1,0) -> 1 | T20: =-7*ln(3300-O20) -> -53.112559 | U20: =-7*ln(3300-R20) -> -53.924295 | V20: =if(N20=1,1/(1+exp(U20-T20)),"") -> 0.69247939 | W20: =power((3300-O20)/200,1.6) -> 38.96663 | X20: =ln(1+exp((2300-O20)/80))/5 -> 2.4334772 | Y20: =if(N20=1,(W20*(S20-V20))*'Säännöt ja ohjeet'!$B$54+X20,"") -> 26.39956 | Z20: =-(S20-1) -> 0 | AA20: =1-V20 -> 0.30752061 | AB20: =power((3300-P20)/200,1.6) -> 46.91068 | AC20: =ln(1+exp((2300-P20)/80))/5 -> 3.0400647 | AD20: =if(N20=1,(AB20*(Z20-AA20))*'Säännöt ja ohjeet'!$B$54+AC20,"") -> -25.811937 | AE20: =10*if($E20=B20,1,-1)+min(10,rounddown((P20-O20)/50,0)-2*$D20*sign(P20-O20))+1 -> 7 | AF20: =10*if($E20=C20,1,-1)+min(10,rounddown((O20-P20)/50,0)-2*$D20*sign(O20-P20))+1 -> -5 | AI20: =if($B20=AI$3,AI19+$Y20,if($C20=AI$3,AI19+$AD20,AI19)) -> 1886.961 | AJ20: =if($B20=AJ$3,AJ19+$Y20,if($C20=AJ$3,AJ19+$AD20,AJ19)) -> 1872.3213 | AK20: =if($B20=AK$3,AK19+$Y20,if($C20=AK$3,AK19+$AD20,AK19)) -> 2437.2544 | AL20: =if($B20=AL$3,AL19+$Y20,if($C20=AL$3,AL19+$AD20,AL19)) -> 1676.0117 | AM20: =if($B20=AM$3,AM19+$Y20,if($C20=AM$3,AM19+$AD20,AM19)) -> 1804.0721 | AN20: =if($B20=AN$3,AN19+$Y20,if($C20=AN$3,AN19+$AD20,AN19)) -> 2324.4055 | AO20: =if($B20=AO$3,AO19+$Y20,if($C20=AO$3,AO19+$AD20,AO19)) -> 2286.3278 | AP20: =if($B20=AP$3,AP19+$Y20,if($C20=AP$3,AP19+$AD20,AP19)) -> 1646.0151 | ... ED20: =if($B20=ED$3,ED19+$Y20,if($C20=ED$3,ED19+$AD20,ED19)) -> #N/A | EE20: =sum(iferror(AI20:BH20,0))/count(AI20:BH20) -> 1654.224
B21: Olli | C21: Peitsa | D21: 5 | E21: Olli | F21: 46117 | H21: =if(countblank(B21:E21)<4,TRUE,FALSE) -> TRUE | I21: =if(iferror(match(B21,'Osallistujat ja seuranta'!C:C,0),0)>0,TRUE,FALSE) -> TRUE | J21: =if(iferror(match(C21,'Osallistujat ja seuranta'!C:C,0),0)>0,TRUE,FALSE) -> TRUE | K21: =not(B21=C21) -> TRUE | L21: =or(E21=B21,E21=C21) -> TRUE | M21: =countblank(B21:E21)=0 -> TRUE | N21: =if(and(I21:M21),1,if(H21,0,"")) -> 1 | O21: =if(N21=1,index(20:20,1,match(B21,$3:$3,0)),"") -> 2437.2544 | P21: =if(N21=1,index(20:20,1,match(C21,$3:$3,0)),"") -> 1872.3213 | Q21: =if(N21=1,O21-(P21+D21*100-if(D21>0,50,0))*N21,"") -> 114.93305 | R21: =if(N21=1,P21+D21*100-if(D21>0,50,0),"") -> 2322.3213 | S21: =if(E21=B21,1,0) -> 1 | T21: =-7*ln(3300-O21) -> -47.320839 | U21: =-7*ln(3300-R21) -> -48.196267 | V21: =if(N21=1,1/(1+exp(U21-T21)),"") -> 0.70587394 | W21: =power((3300-O21)/200,1.6) -> 10.369658 | X21: =ln(1+exp((2300-O21)/80))/5 -> 0.033076004 | Y21: =if(N21=1,(W21*(S21-V21))*'Säännöt ja ohjeet'!$B$54+X21,"") -> 6.1330491 | Z21: =-(S21-1) -> 0 | AA21: =1-V21 -> 0.29412606 | AB21: =power((3300-P21)/200,1.6) -> 23.214576 | AC21: =ln(1+exp((2300-P21)/80))/5 -> 1.0701478 | AD21: =if(N21=1,(AB21*(Z21-AA21))*'Säännöt ja ohjeet'!$B$54+AC21,"") -> -12.585876 | AE21: =10*if($E21=B21,1,-1)+min(10,rounddown((P21-O21)/50,0)-2*$D21*sign(P21-O21))+1 -> 10 | AF21: =10*if($E21=C21,1,-1)+min(10,rounddown((O21-P21)/50,0)-2*$D21*sign(O21-P21))+1 -> -8 | AI21: =if($B21=AI$3,AI20+$Y21,if($C21=AI$3,AI20+$AD21,AI20)) -> 1886.961 | AJ21: =if($B21=AJ$3,AJ20+$Y21,if($C21=AJ$3,AJ20+$AD21,AJ20)) -> 1859.7355 | AK21: =if($B21=AK$3,AK20+$Y21,if($C21=AK$3,AK20+$AD21,AK20)) -> 2443.3874 | AL21: =if($B21=AL$3,AL20+$Y21,if($C21=AL$3,AL20+$AD21,AL20)) -> 1676.0117 | AM21: =if($B21=AM$3,AM20+$Y21,if($C21=AM$3,AM20+$AD21,AM20)) -> 1804.0721 | AN21: =if($B21=AN$3,AN20+$Y21,if($C21=AN$3,AN20+$AD21,AN20)) -> 2324.4055 | AO21: =if($B21=AO$3,AO20+$Y21,if($C21=AO$3,AO20+$AD21,AO20)) -> 2286.3278 | AP21: =if($B21=AP$3,AP20+$Y21,if($C21=AP$3,AP20+$AD21,AP20)) -> 1646.0151 | ... ED21: =if($B21=ED$3,ED20+$Y21,if($C21=ED$3,ED20+$AD21,ED20)) -> #N/A | EE21: =sum(iferror(AI21:BH21,0))/count(AI21:BH21) -> 1653.9167
B22: Jussa | C22: Lauri | D22: 0 | E22: Jussa | F22: 46117 | H22: =if(countblank(B22:E22)<4,TRUE,FALSE) -> TRUE | I22: =if(iferror(match(B22,'Osallistujat ja seuranta'!C:C,0),0)>0,TRUE,FALSE) -> TRUE | J22: =if(iferror(match(C22,'Osallistujat ja seuranta'!C:C,0),0)>0,TRUE,FALSE) -> TRUE | K22: =not(B22=C22) -> TRUE | L22: =or(E22=B22,E22=C22) -> TRUE | M22: =countblank(B22:E22)=0 -> TRUE | N22: =if(and(I22:M22),1,if(H22,0,"")) -> 1 | O22: =if(N22=1,index(21:21,1,match(B22,$3:$3,0)),"") -> 1886.961 | P22: =if(N22=1,index(21:21,1,match(C22,$3:$3,0)),"") -> 1676.0117 | Q22: =if(N22=1,O22-(P22+D22*100-if(D22>0,50,0))*N22,"") -> 210.94931 | R22: =if(N22=1,P22+D22*100-if(D22>0,50,0),"") -> 1676.0117 | S22: =if(E22=B22,1,0) -> 1 | T22: =-7*ln(3300-O22) -> -50.774486 | U22: =-7*ln(3300-R22) -> -51.748482 | V22: =if(N22=1,1/(1+exp(U22-T22)),"") -> 0.72591535 | W22: =power((3300-O22)/200,1.6) -> 22.834874 | X22: =ln(1+exp((2300-O22)/80))/5 -> 1.0337391 | Y22: =if(N22=1,(W22*(S22-V22))*'Säännöt ja ohjeet'!$B$54+X22,"") -> 13.551116 | Z22: =-(S22-1) -> 0 | AA22: =1-V22 -> 0.27408465 | AB22: =power((3300-P22)/200,1.6) -> 28.528874 | AC22: =ln(1+exp((2300-P22)/80))/5 -> 1.5600526 | AD22: =if(N22=1,(AB22*(Z22-AA22))*'Säännöt ja ohjeet'!$B$54+AC22,"") -> -14.0786 | AE22: =10*if($E22=B22,1,-1)+min(10,rounddown((P22-O22)/50,0)-2*$D22*sign(P22-O22))+1 -> 7 | AF22: =10*if($E22=C22,1,-1)+min(10,rounddown((O22-P22)/50,0)-2*$D22*sign(O22-P22))+1 -> -5 | AI22: =if($B22=AI$3,AI21+$Y22,if($C22=AI$3,AI21+$AD22,AI21)) -> 1900.5122 | AJ22: =if($B22=AJ$3,AJ21+$Y22,if($C22=AJ$3,AJ21+$AD22,AJ21)) -> 1859.7355 | AK22: =if($B22=AK$3,AK21+$Y22,if($C22=AK$3,AK21+$AD22,AK21)) -> 2443.3874 | AL22: =if($B22=AL$3,AL21+$Y22,if($C22=AL$3,AL21+$AD22,AL21)) -> 1661.9331 | AM22: =if($B22=AM$3,AM21+$Y22,if($C22=AM$3,AM21+$AD22,AM21)) -> 1804.0721 | AN22: =if($B22=AN$3,AN21+$Y22,if($C22=AN$3,AN21+$AD22,AN21)) -> 2324.4055 | AO22: =if($B22=AO$3,AO21+$Y22,if($C22=AO$3,AO21+$AD22,AO21)) -> 2286.3278 | AP22: =if($B22=AP$3,AP21+$Y22,if($C22=AP$3,AP21+$AD22,AP21)) -> 1646.0151 | ... ED22: =if($B22=ED$3,ED21+$Y22,if($C22=ED$3,ED21+$AD22,ED21)) -> #N/A | EE22: =sum(iferror(AI22:BH22,0))/count(AI22:BH22) -> 1653.8916
B23: Timo | C23: Jussa | D23: 4 | E23: Jussa | F23: 46117 | H23: =if(countblank(B23:E23)<4,TRUE,FALSE) -> TRUE | I23: =if(iferror(match(B23,'Osallistujat ja seuranta'!C:C,0),0)>0,TRUE,FALSE) -> TRUE | J23: =if(iferror(match(C23,'Osallistujat ja seuranta'!C:C,0),0)>0,TRUE,FALSE) -> TRUE | K23: =not(B23=C23) -> TRUE | L23: =or(E23=B23,E23=C23) -> TRUE | M23: =countblank(B23:E23)=0 -> TRUE | N23: =if(and(I23:M23),1,if(H23,0,"")) -> 1 | O23: =if(N23=1,index(22:22,1,match(B23,$3:$3,0)),"") -> 2324.4055 | P23: =if(N23=1,index(22:22,1,match(C23,$3:$3,0)),"") -> 1900.5122 | Q23: =if(N23=1,O23-(P23+D23*100-if(D23>0,50,0))*N23,"") -> 73.89335 | R23: =if(N23=1,P23+D23*100-if(D23>0,50,0),"") -> 2250.5122 | S23: =if(E23=B23,1,0) -> 0 | T23: =-7*ln(3300-O23) -> -48.181329 | U23: =-7*ln(3300-R23) -> -48.692403 | V23: =if(N23=1,1/(1+exp(U23-T23)),"") -> 0.62505815 | W23: =power((3300-O23)/200,1.6) -> 12.623592 | X23: =ln(1+exp((2300-O23)/80))/5 -> 0.11044027 | Y23: =if(N23=1,(W23*(S23-V23))*'Säännöt ja ohjeet'!$B$54+X23,"") -> -15.670518 | Z23: =-(S23-1) -> 1 | AA23: =1-V23 -> 0.37494185 | AB23: =power((3300-P23)/200,1.6) -> 22.485504 | AC23: =ln(1+exp((2300-P23)/80))/5 -> 1.0000713 | AD23: =if(N23=1,(AB23*(Z23-AA23))*'Säännöt ja ohjeet'!$B$54+AC23,"") -> 29.109566 | AE23: =10*if($E23=B23,1,-1)+min(10,rounddown((P23-O23)/50,0)-2*$D23*sign(P23-O23))+1 -> -9 | AF23: =10*if($E23=C23,1,-1)+min(10,rounddown((O23-P23)/50,0)-2*$D23*sign(O23-P23))+1 -> 11 | AI23: =if($B23=AI$3,AI22+$Y23,if($C23=AI$3,AI22+$AD23,AI22)) -> 1929.6217 | AJ23: =if($B23=AJ$3,AJ22+$Y23,if($C23=AJ$3,AJ22+$AD23,AJ22)) -> 1859.7355 | AK23: =if($B23=AK$3,AK22+$Y23,if($C23=AK$3,AK22+$AD23,AK22)) -> 2443.3874 | AL23: =if($B23=AL$3,AL22+$Y23,if($C23=AL$3,AL22+$AD23,AL22)) -> 1661.9331 | AM23: =if($B23=AM$3,AM22+$Y23,if($C23=AM$3,AM22+$AD23,AM22)) -> 1804.0721 | AN23: =if($B23=AN$3,AN22+$Y23,if($C23=AN$3,AN22+$AD23,AN22)) -> 2308.735 | AO23: =if($B23=AO$3,AO22+$Y23,if($C23=AO$3,AO22+$AD23,AO22)) -> 2286.3278 | AP23: =if($B23=AP$3,AP22+$Y23,if($C23=AP$3,AP22+$AD23,AP22)) -> 1646.0151 | ... ED23: =if($B23=ED$3,ED22+$Y23,if($C23=ED$3,ED22+$AD23,ED22)) -> #N/A | EE23: =sum(iferror(AI23:BH23,0))/count(AI23:BH23) -> 1654.5315
B24: Jussa | C24: Olli | D24: 5 | E24: Olli | F24: 46120 | H24: =if(countblank(B24:E24)<4,TRUE,FALSE) -> TRUE | I24: =if(iferror(match(B24,'Osallistujat ja seuranta'!C:C,0),0)>0,TRUE,FALSE) -> TRUE | J24: =if(iferror(match(C24,'Osallistujat ja seuranta'!C:C,0),0)>0,TRUE,FALSE) -> TRUE | K24: =not(B24=C24) -> TRUE | L24: =or(E24=B24,E24=C24) -> TRUE | M24: =countblank(B24:E24)=0 -> TRUE | N24: =if(and(I24:M24),1,if(H24,0,"")) -> 1 | O24: =if(N24=1,index(23:23,1,match(B24,$3:$3,0)),"") -> 1929.6217 | P24: =if(N24=1,index(23:23,1,match(C24,$3:$3,0)),"") -> 2443.3874 | Q24: =if(N24=1,O24-(P24+D24*100-if(D24>0,50,0))*N24,"") -> -963.76573 | R24: =if(N24=1,P24+D24*100-if(D24>0,50,0),"") -> 2893.3874 | S24: =if(E24=B24,1,0) -> 0 | T24: =-7*ln(3300-O24) -> -50.559895 | U24: =-7*ln(3300-R24) -> -42.055025 | V24: =if(N24=1,1/(1+exp(U24-T24)),"") -> 0.00020243905 | W24: =power((3300-O24)/200,1.6) -> 21.741863 | X24: =ln(1+exp((2300-O24)/80))/5 -> 0.92788773 | Y24: =if(N24=1,(W24*(S24-V24))*'Säännöt ja ohjeet'!$B$54+X24,"") -> 0.91908493 | Z24: =-(S24-1) -> 1 | AA24: =1-V24 -> 0.99979756 | AB24: =power((3300-P24)/200,1.6) -> 10.251965 | AC24: =ln(1+exp((2300-P24)/80))/5 -> 0.030813466 | AD24: =if(N24=1,(AB24*(Z24-AA24))*'Säännöt ja ohjeet'!$B$54+AC24,"") -> 0.034964262 | AE24: =10*if($E24=B24,1,-1)+min(10,rounddown((P24-O24)/50,0)-2*$D24*sign(P24-O24))+1 -> -9 | AF24: =10*if($E24=C24,1,-1)+min(10,rounddown((O24-P24)/50,0)-2*$D24*sign(O24-P24))+1 -> 11 | AI24: =if($B24=AI$3,AI23+$Y24,if($C24=AI$3,AI23+$AD24,AI23)) -> 1930.5408 | AJ24: =if($B24=AJ$3,AJ23+$Y24,if($C24=AJ$3,AJ23+$AD24,AJ23)) -> 1859.7355 | AK24: =if($B24=AK$3,AK23+$Y24,if($C24=AK$3,AK23+$AD24,AK23)) -> 2443.4224 | AL24: =if($B24=AL$3,AL23+$Y24,if($C24=AL$3,AL23+$AD24,AL23)) -> 1661.9331 | AM24: =if($B24=AM$3,AM23+$Y24,if($C24=AM$3,AM23+$AD24,AM23)) -> 1804.0721 | AN24: =if($B24=AN$3,AN23+$Y24,if($C24=AN$3,AN23+$AD24,AN23)) -> 2308.735 | AO24: =if($B24=AO$3,AO23+$Y24,if($C24=AO$3,AO23+$AD24,AO23)) -> 2286.3278 | AP24: =if($B24=AP$3,AP23+$Y24,if($C24=AP$3,AP23+$AD24,AP23)) -> 1646.0151 | ... ED24: =if($B24=ED$3,ED23+$Y24,if($C24=ED$3,ED23+$AD24,ED23)) -> #N/A | EE24: =sum(iferror(AI24:BH24,0))/count(AI24:BH24) -> 1654.577
B25: Olli | C25: Kulkija | D25: 7 | E25: Olli | F25: 46120 | H25: =if(countblank(B25:E25)<4,TRUE,FALSE) -> TRUE | I25: =if(iferror(match(B25,'Osallistujat ja seuranta'!C:C,0),0)>0,TRUE,FALSE) -> TRUE | J25: =if(iferror(match(C25,'Osallistujat ja seuranta'!C:C,0),0)>0,TRUE,FALSE) -> TRUE | K25: =not(B25=C25) -> TRUE | L25: =or(E25=B25,E25=C25) -> TRUE | M25: =countblank(B25:E25)=0 -> TRUE | N25: =if(and(I25:M25),1,if(H25,0,"")) -> 1 | O25: =if(N25=1,index(24:24,1,match(B25,$3:$3,0)),"") -> 2443.4224 | P25: =if(N25=1,index(24:24,1,match(C25,$3:$3,0)),"") -> 1353.0091 | Q25: =if(N25=1,O25-(P25+D25*100-if(D25>0,50,0))*N25,"") -> 440.4133 | R25: =if(N25=1,P25+D25*100-if(D25>0,50,0),"") -> 2003.0091 | S25: =if(E25=B25,1,0) -> 1 | T25: =-7*ln(3300-O25) -> -47.270614 | U25: =-7*ln(3300-R25) -> -50.174615 | V25: =if(N25=1,1/(1+exp(U25-T25)),"") -> 0.94804386 | W25: =power((3300-O25)/200,1.6) -> 10.251295 | X25: =ln(1+exp((2300-O25)/80))/5 -> 0.030800987 | Y25: =if(N25=1,(W25*(S25-V25))*'Säännöt ja ohjeet'!$B$54+X25,"") -> 1.0960365 | Z25: =-(S25-1) -> 0 | AA25: =1-V25 -> 0.051956143 | AB25: =power((3300-P25)/200,1.6) -> 38.135924 | AC25: =ln(1+exp((2300-P25)/80))/5 -> 2.3674787 | AD25: =if(N25=1,(AB25*(Z25-AA25))*'Säännöt ja ohjeet'!$B$54+AC25,"") -> -1.5953124 | AE25: =10*if($E25=B25,1,-1)+min(10,rounddown((P25-O25)/50,0)-2*$D25*sign(P25-O25))+1 -> 4 | AF25: =10*if($E25=C25,1,-1)+min(10,rounddown((O25-P25)/50,0)-2*$D25*sign(O25-P25))+1 -> -2 | AI25: =if($B25=AI$3,AI24+$Y25,if($C25=AI$3,AI24+$AD25,AI24)) -> 1930.5408 | AJ25: =if($B25=AJ$3,AJ24+$Y25,if($C25=AJ$3,AJ24+$AD25,AJ24)) -> 1859.7355 | AK25: =if($B25=AK$3,AK24+$Y25,if($C25=AK$3,AK24+$AD25,AK24)) -> 2444.5184 | AL25: =if($B25=AL$3,AL24+$Y25,if($C25=AL$3,AL24+$AD25,AL24)) -> 1661.9331 | AM25: =if($B25=AM$3,AM24+$Y25,if($C25=AM$3,AM24+$AD25,AM24)) -> 1804.0721 | AN25: =if($B25=AN$3,AN24+$Y25,if($C25=AN$3,AN24+$AD25,AN24)) -> 2308.735 | AO25: =if($B25=AO$3,AO24+$Y25,if($C25=AO$3,AO24+$AD25,AO24)) -> 2286.3278 | AP25: =if($B25=AP$3,AP24+$Y25,if($C25=AP$3,AP24+$AD25,AP24)) -> 1646.0151 | ... ED25: =if($B25=ED$3,ED24+$Y25,if($C25=ED$3,ED24+$AD25,ED24)) -> #N/A | EE25: =sum(iferror(AI25:BH25,0))/count(AI25:BH25) -> 1654.5532
B26: Peitsa | C26: Ilia | D26: 7 | E26: Peitsa | F26: 46120 | H26: =if(countblank(B26:E26)<4,TRUE,FALSE) -> TRUE | I26: =if(iferror(match(B26,'Osallistujat ja seuranta'!C:C,0),0)>0,TRUE,FALSE) -> TRUE | J26: =if(iferror(match(C26,'Osallistujat ja seuranta'!C:C,0),0)>0,TRUE,FALSE) -> TRUE | K26: =not(B26=C26) -> TRUE | L26: =or(E26=B26,E26=C26) -> TRUE | M26: =countblank(B26:E26)=0 -> TRUE | N26: =if(and(I26:M26),1,if(H26,0,"")) -> 1 | O26: =if(N26=1,index(25:25,1,match(B26,$3:$3,0)),"") -> 1859.7355 | P26: =if(N26=1,index(25:25,1,match(C26,$3:$3,0)),"") -> 883.85095 | Q26: =if(N26=1,O26-(P26+D26*100-if(D26>0,50,0))*N26,"") -> 325.88452 | R26: =if(N26=1,P26+D26*100-if(D26>0,50,0),"") -> 1533.851 | S26: =if(E26=B26,1,0) -> 1 | T26: =-7*ln(3300-O26) -> -50.908075 | U26: =-7*ln(3300-R26) -> -52.335897 | V26: =if(N26=1,1/(1+exp(U26-T26)),"") -> 0.80656187 | W26: =power((3300-O26)/200,1.6) -> 23.542882 | X26: =ln(1+exp((2300-O26)/80))/5 -> 1.1014743 | Y26: =if(N26=1,(W26*(S26-V26))*'Säännöt ja ohjeet'!$B$54+X26,"") -> 10.209656 | Z26: =-(S26-1) -> 0 | AA26: =1-V26 -> 0.19343813 | AB26: =power((3300-P26)/200,1.6) -> 53.87037 | AC26: =ln(1+exp((2300-P26)/80))/5 -> 3.5403726 | AD26: =if(N26=1,(AB26*(Z26-AA26))*'Säännöt ja ohjeet'!$B$54+AC26,"") -> -17.300795 | AE26: =10*if($E26=B26,1,-1)+min(10,rounddown((P26-O26)/50,0)-2*$D26*sign(P26-O26))+1 -> 6 | AF26: =10*if($E26=C26,1,-1)+min(10,rounddown((O26-P26)/50,0)-2*$D26*sign(O26-P26))+1 -> -4 | AI26: =if($B26=AI$3,AI25+$Y26,if($C26=AI$3,AI25+$AD26,AI25)) -> 1930.5408 | AJ26: =if($B26=AJ$3,AJ25+$Y26,if($C26=AJ$3,AJ25+$AD26,AJ25)) -> 1869.9451 | AK26: =if($B26=AK$3,AK25+$Y26,if($C26=AK$3,AK25+$AD26,AK25)) -> 2444.5184 | AL26: =if($B26=AL$3,AL25+$Y26,if($C26=AL$3,AL25+$AD26,AL25)) -> 1661.9331 | AM26: =if($B26=AM$3,AM25+$Y26,if($C26=AM$3,AM25+$AD26,AM25)) -> 1804.0721 | AN26: =if($B26=AN$3,AN25+$Y26,if($C26=AN$3,AN25+$AD26,AN25)) -> 2308.735 | AO26: =if($B26=AO$3,AO25+$Y26,if($C26=AO$3,AO25+$AD26,AO25)) -> 2286.3278 | AP26: =if($B26=AP$3,AP25+$Y26,if($C26=AP$3,AP25+$AD26,AP25)) -> 1646.0151 | ... ED26: =if($B26=ED$3,ED25+$Y26,if($C26=ED$3,ED25+$AD26,ED25)) -> #N/A | EE26: =sum(iferror(AI26:BH26,0))/count(AI26:BH26) -> 1654.2155
B27: Olli | C27: Teemu | D27: 1 | E27: Olli | F27: 46124 | H27: =if(countblank(B27:E27)<4,TRUE,FALSE) -> TRUE | I27: =if(iferror(match(B27,'Osallistujat ja seuranta'!C:C,0),0)>0,TRUE,FALSE) -> TRUE | J27: =if(iferror(match(C27,'Osallistujat ja seuranta'!C:C,0),0)>0,TRUE,FALSE) -> TRUE | K27: =not(B27=C27) -> TRUE | L27: =or(E27=B27,E27=C27) -> TRUE | M27: =countblank(B27:E27)=0 -> TRUE | N27: =if(and(I27:M27),1,if(H27,0,"")) -> 1 | O27: =if(N27=1,index(26:26,1,match(B27,$3:$3,0)),"") -> 2444.5184 | P27: =if(N27=1,index(26:26,1,match(C27,$3:$3,0)),"") -> 2183.965 | Q27: =if(N27=1,O27-(P27+D27*100-if(D27>0,50,0))*N27,"") -> 210.5534 | R27: =if(N27=1,P27+D27*100-if(D27>0,50,0),"") -> 2233.965 | S27: =if(E27=B27,1,0) -> 1 | T27: =-7*ln(3300-O27) -> -47.261652 | U27: =-7*ln(3300-R27) -> -48.80191 | V27: =if(N27=1,1/(1+exp(U27-T27)),"") -> 0.82350223 | W27: =power((3300-O27)/200,1.6) -> 10.230316 | X27: =ln(1+exp((2300-O27)/80))/5 -> 0.030412177 | Y27: =if(N27=1,(W27*(S27-V27))*'Säännöt ja ohjeet'!$B$54+X27,"") -> 3.641668 | Z27: =-(S27-1) -> 0 | AA27: =1-V27 -> 0.17649777 | AB27: =power((3300-P27)/200,1.6) -> 15.654402 | AC27: =ln(1+exp((2300-P27)/80))/5 -> 0.33221537 | AD27: =if(N27=1,(AB27*(Z27-AA27))*'Säännöt ja ohjeet'!$B$54+AC27,"") -> -5.1937186 | AE27: =10*if($E27=B27,1,-1)+min(10,rounddown((P27-O27)/50,0)-2*$D27*sign(P27-O27))+1 -> 8 | AF27: =10*if($E27=C27,1,-1)+min(10,rounddown((O27-P27)/50,0)-2*$D27*sign(O27-P27))+1 -> -6 | AI27: =if($B27=AI$3,AI26+$Y27,if($C27=AI$3,AI26+$AD27,AI26)) -> 1930.5408 | AJ27: =if($B27=AJ$3,AJ26+$Y27,if($C27=AJ$3,AJ26+$AD27,AJ26)) -> 1869.9451 | AK27: =if($B27=AK$3,AK26+$Y27,if($C27=AK$3,AK26+$AD27,AK26)) -> 2448.1601 | AL27: =if($B27=AL$3,AL26+$Y27,if($C27=AL$3,AL26+$AD27,AL26)) -> 1661.9331 | AM27: =if($B27=AM$3,AM26+$Y27,if($C27=AM$3,AM26+$AD27,AM26)) -> 1804.0721 | AN27: =if($B27=AN$3,AN26+$Y27,if($C27=AN$3,AN26+$AD27,AN26)) -> 2308.735 | AO27: =if($B27=AO$3,AO26+$Y27,if($C27=AO$3,AO26+$AD27,AO26)) -> 2286.3278 | AP27: =if($B27=AP$3,AP26+$Y27,if($C27=AP$3,AP26+$AD27,AP26)) -> 1646.0151 | ... ED27: =if($B27=ED$3,ED26+$Y27,if($C27=ED$3,ED26+$AD27,ED26)) -> #N/A | EE27: =sum(iferror(AI27:BH27,0))/count(AI27:BH27) -> 1654.1416
B28: Olli | C28: Janne L | D28: 9 | E28: Olli | F28: 46127 | H28: =if(countblank(B28:E28)<4,TRUE,FALSE) -> TRUE | I28: =if(iferror(match(B28,'Osallistujat ja seuranta'!C:C,0),0)>0,TRUE,FALSE) -> TRUE | J28: =if(iferror(match(C28,'Osallistujat ja seuranta'!C:C,0),0)>0,TRUE,FALSE) -> TRUE | K28: =not(B28=C28) -> TRUE | L28: =or(E28=B28,E28=C28) -> TRUE | M28: =countblank(B28:E28)=0 -> TRUE | N28: =if(and(I28:M28),1,if(H28,0,"")) -> 1 | O28: =if(N28=1,index(27:27,1,match(B28,$3:$3,0)),"") -> 2448.1601 | P28: =if(N28=1,index(27:27,1,match(C28,$3:$3,0)),"") -> 1058.1622 | Q28: =if(N28=1,O28-(P28+D28*100-if(D28>0,50,0))*N28,"") -> 539.99793 | R28: =if(N28=1,P28+D28*100-if(D28>0,50,0),"") -> 1908.1622 | S28: =if(E28=B28,1,0) -> 1 | T28: =-7*ln(3300-O28) -> -47.23179 | U28: =-7*ln(3300-R28) -> -50.668662 | V28: =if(N28=1,1/(1+exp(U28-T28)),"") -> 0.96883722 | W28: =power((3300-O28)/200,1.6) -> 10.160726 | X28: =ln(1+exp((2300-O28)/80))/5 -> 0.029152741 | Y28: =if(N28=1,(W28*(S28-V28))*'Säännöt ja ohjeet'!$B$54+X28,"") -> 0.66242572 | Z28: =-(S28-1) -> 0 | AA28: =1-V28 -> 0.03116278 | AB28: =power((3300-P28)/200,1.6) -> 47.787984 | AC28: =ln(1+exp((2300-P28)/80))/5 -> 3.1045946 | AD28: =if(N28=1,(AB28*(Z28-AA28))*'Säännöt ja ohjeet'!$B$54+AC28,"") -> 0.12618166 | AE28: =10*if($E28=B28,1,-1)+min(10,rounddown((P28-O28)/50,0)-2*$D28*sign(P28-O28))+1 -> 2 | AF28: =10*if($E28=C28,1,-1)+min(10,rounddown((O28-P28)/50,0)-2*$D28*sign(O28-P28))+1 -> 0 | AI28: =if($B28=AI$3,AI27+$Y28,if($C28=AI$3,AI27+$AD28,AI27)) -> 1930.5408 | AJ28: =if($B28=AJ$3,AJ27+$Y28,if($C28=AJ$3,AJ27+$AD28,AJ27)) -> 1869.9451 | AK28: =if($B28=AK$3,AK27+$Y28,if($C28=AK$3,AK27+$AD28,AK27)) -> 2448.8225 | AL28: =if($B28=AL$3,AL27+$Y28,if($C28=AL$3,AL27+$AD28,AL27)) -> 1661.9331 | AM28: =if($B28=AM$3,AM27+$Y28,if($C28=AM$3,AM27+$AD28,AM27)) -> 1804.0721 | AN28: =if($B28=AN$3,AN27+$Y28,if($C28=AN$3,AN27+$AD28,AN27)) -> 2308.735 | AO28: =if($B28=AO$3,AO27+$Y28,if($C28=AO$3,AO27+$AD28,AO27)) -> 2286.3278 | AP28: =if($B28=AP$3,AP27+$Y28,if($C28=AP$3,AP27+$AD28,AP27)) -> 1646.0151 | ... ED28: =if($B28=ED$3,ED27+$Y28,if($C28=ED$3,ED27+$AD28,ED27)) -> #N/A | EE28: =sum(iferror(AI28:BH28,0))/count(AI28:BH28) -> 1654.1792
B29: Olli | C29: Jussa | D29: 4 | E29: Olli | F29: 46127 | H29: =if(countblank(B29:E29)<4,TRUE,FALSE) -> TRUE | I29: =if(iferror(match(B29,'Osallistujat ja seuranta'!C:C,0),0)>0,TRUE,FALSE) -> TRUE | J29: =if(iferror(match(C29,'Osallistujat ja seuranta'!C:C,0),0)>0,TRUE,FALSE) -> TRUE | K29: =not(B29=C29) -> TRUE | L29: =or(E29=B29,E29=C29) -> TRUE | M29: =countblank(B29:E29)=0 -> TRUE | N29: =if(and(I29:M29),1,if(H29,0,"")) -> 1 | O29: =if(N29=1,index(28:28,1,match(B29,$3:$3,0)),"") -> 2448.8225 | P29: =if(N29=1,index(28:28,1,match(C29,$3:$3,0)),"") -> 1930.5408 | Q29: =if(N29=1,O29-(P29+D29*100-if(D29>0,50,0))*N29,"") -> 168.28174 | R29: =if(N29=1,P29+D29*100-if(D29>0,50,0),"") -> 2280.5408 | S29: =if(E29=B29,1,0) -> 1 | T29: =-7*ln(3300-O29) -> -47.226344 | U29: =-7*ln(3300-R29) -> -48.489193 | V29: =if(N29=1,1/(1+exp(U29-T29)),"") -> 0.77951607 | W29: =power((3300-O29)/200,1.6) -> 10.148087 | X29: =ln(1+exp((2300-O29)/80))/5 -> 0.028928918 | Y29: =if(N29=1,(W29*(S29-V29))*'Säännöt ja ohjeet'!$B$54+X29,"") -> 4.5039091 | Z29: =-(S29-1) -> 0 | AA29: =1-V29 -> 0.22048393 | AB29: =power((3300-P29)/200,1.6) -> 21.718537 | AC29: =ln(1+exp((2300-P29)/80))/5 -> 0.92561235 | AD29: =if(N29=1,(AB29*(Z29-AA29))*'Säännöt ja ohjeet'!$B$54+AC29,"") -> -8.6515642 | AE29: =10*if($E29=B29,1,-1)+min(10,rounddown((P29-O29)/50,0)-2*$D29*sign(P29-O29))+1 -> 9 | AF29: =10*if($E29=C29,1,-1)+min(10,rounddown((O29-P29)/50,0)-2*$D29*sign(O29-P29))+1 -> -7 | AI29: =if($B29=AI$3,AI28+$Y29,if($C29=AI$3,AI28+$AD29,AI28)) -> 1921.8892 | AJ29: =if($B29=AJ$3,AJ28+$Y29,if($C29=AJ$3,AJ28+$AD29,AJ28)) -> 1869.9451 | AK29: =if($B29=AK$3,AK28+$Y29,if($C29=AK$3,AK28+$AD29,AK28)) -> 2453.3264 | AL29: =if($B29=AL$3,AL28+$Y29,if($C29=AL$3,AL28+$AD29,AL28)) -> 1661.9331 | AM29: =if($B29=AM$3,AM28+$Y29,if($C29=AM$3,AM28+$AD29,AM28)) -> 1804.0721 | AN29: =if($B29=AN$3,AN28+$Y29,if($C29=AN$3,AN28+$AD29,AN28)) -> 2308.735 | AO29: =if($B29=AO$3,AO28+$Y29,if($C29=AO$3,AO28+$AD29,AO28)) -> 2286.3278 | AP29: =if($B29=AP$3,AP28+$Y29,if($C29=AP$3,AP28+$AD29,AP28)) -> 1646.0151 | ... ED29: =if($B29=ED$3,ED28+$Y29,if($C29=ED$3,ED28+$AD29,ED28)) -> #N/A | EE29: =sum(iferror(AI29:BH29,0))/count(AI29:BH29) -> 1653.9817
